Workbook
Name WF: Warframe!$J$53

Sheet Main + Info
A1: w
B2: WARFRAME Mastery Checklist - Update 42 - Feel free to make a copy
B3: Important: | C3: Original layout by /u/Sekwah, adjusted by /u/Tykras. Updated for 26.1 by /u/FrToast. Updated for 30.0 by Xenotater | L3: The Wiki | M3: https://wiki.warframe.com/
C4: I suggest using Google Chrome to visualize this sheet at 100% zoom and 1920x1080 resolution
C5: Recent Additions: Update 35 Dante Unbound
C6: Re-edited by wulfhart and DitzybDoo. Please message with any issues. Fixed some errors in weapon placement, and some masteries not counting
C7: Re-edited for U39 by /u/Vansceslas (because I needed a checklist and this was the prettiest I found). Some weird things were done and I did my best to fix things I saw were obviously wrong No alterations were done to the Planets/Junctions because I have no idea what changed since U35 and I didn't want to be spoiled Message me if there is something to fix Updated to 39.1 (Caliban Prime, Venato Prime, Vadarya Prime) ; Added a Subsumed Column for Warframes Updating the acquisitions methods for all items (Warframe and all Prime checked ; Weapon as component remarks added) Updated for U40: The Vallis Undermind (Nokko, Thornbak, Arbucep, also Prime Archguns were not properly counted) Updated for U41: The Old Peace (Uriel, Gyre Prime, Vinquibus, Alternox Prime, Kestrel Prime, Galariak Prime & Sagek Prime. I also fixed a minor issue for the Coda & Tenet Primary mastery calculations) Updated for U42: The Shadowgrapher (Follie, Enkaus, Kuva Ghoulsaw, Tenet Quanta, Coda Bubonico, as well as some modifications to the "Acquisition" remarks, added Legendary Mastery Ranks).Later added Voruna Prime, Perigale Prime & Sarofang Prime
Q15: Mastery Rank | R15: Affinity Needed
B16: Planets | C16: # Missions | D16: Completed | E16: Steel Path | G16: Junctions | H16: Completed | I16: Steel Path | K16: Item | L16: Owned | N16: Item | O16: Completion | Q16: MR0 | R16: 0
B17: Mercury | C17: 11 | D17: FALSE | E17: FALSE | G17: Mercury | H17: FALSE | I17: FALSE | K17: Warframe | L17: =Warframe!N6&"/"&Warframe!O7 -> 80/114 | N17: Warframe | O17: =Warframe!O6&"/"&Warframe!O7 -> 74/114 | Q17: MR1 | R17: 2500
B18: Venus | C18: 15 | D18: FALSE | E18: FALSE | G18: Venus | H18: FALSE | I18: FALSE | K18: Primary | L18: =(Primary!R15)&"/"&(Primary!S16) -> 121/192 | N18: Primary | O18: =(Primary!S15)&"/"&(Primary!S16) -> 80/192 | Q18: MR2 | R18: 10000
B19: Earth | C19: 15 | D19: FALSE | E19: FALSE | G19: Mars | H19: FALSE | I19: FALSE | K19: Secondary | L19: =Secondary!S12&"/"&Secondary!T13 -> 93/151 | N19: Secondary | O19: =Secondary!T12&"/"&Secondary!T13 -> 75/151 | Q19: MR3 | R19: 22500
B20: Lua | C20: 8 | D20: FALSE | E20: FALSE | G20: Phobos | H20: FALSE | I20: FALSE | K20: Melee | L20: =Melee!W29&"/"&Melee!X30 -> 121/231 | N20: Melee | O20: =Melee!X29&"/"&Melee!X30 -> 99/231 | Q20: MR4 | R20: 40000
B21: Mars | C21: 18 | D21: FALSE | E21: FALSE | G21: Ceres | H21: FALSE | I21: FALSE | K21: Robotic | L21: =(Companion!M5+Companion!M9)&"/"&(Companion!N6+Companion!N10) -> 27/41 | N21: Robotic | O21: =(Companion!N5+Companion!N9)&"/"&(Companion!N6+Companion!N10) -> 24/41 | Q21: MR5 | R21: 62500
B22: Deimos | C22: 15 | D22: FALSE | E22: FALSE | G22: Jupiter | H22: FALSE | I22: FALSE | K22: Companion | L22: =(Companion!M17)&"/"&(Companion!N18) -> 12/24 | N22: Companion | O22: =(Companion!N17)&"/"&(Companion!N18) -> 12/24 | Q22: MR6 | R22: 90000
B23: Phobos | C23: 11 | D23: FALSE | E23: FALSE | G23: Europa | H23: FALSE | I23: FALSE | K23: Vehicles | L23: =(Vehicle!H5+Vehicle!H14+Vehicle!H16+COUNTIF(Vehicle!H22,"TRUE"))&"/"&(Vehicle!I6+Vehicle!I15+Vehicle!I17+COUNTA(Vehicle!H22)) -> 7/13 | N23: Vehicles | O23: =(Vehicle!I5+Vehicle!I14+Vehicle!I16+COUNTIF(Vehicle!H22,"TRUE"))&"/"&(Vehicle!I6+Vehicle!I15+Vehicle!I17+COUNTA(Vehicle!H22)) -> 6/13 | Q23: MR7 | R23: 122500
B24: Ceres | C24: 14 | D24: FALSE | E24: FALSE | G24: Saturn | H24: FALSE | I24: FALSE | K24: Arch-Gun | L24: =Vehicle!H9&"/"&Vehicle!I10 -> 8/21 | N24: Arch-Gun | O24: =Vehicle!I9&"/"&Vehicle!I10 -> 2/21 | Q24: MR8 | R24: 160000
B25: Jupiter | C25: 16 | D25: FALSE | E25: FALSE | G25: Uranus | H25: FALSE | I25: FALSE | K25: Arch-Melee | L25: =Vehicle!H12&"/"&Vehicle!I13 -> 1/8 | N25: Arch-Melee | O25: =Vehicle!I12&"/"&Vehicle!I13 -> 1/8 | Q25: MR9 | R25: 202500
B26: Europa | C26: 14 | D26: FALSE | E26: FALSE | G26: Neptune | H26: FALSE | I26: FALSE | K26: Amp | L26: =AmpDrifter!H3&"/"&AmpDrifter!I4 -> 5/10 | N26: Amp | O26: =AmpDrifter!I3&"/"&AmpDrifter!I4 -> 5/10 | Q26: MR10 | R26: 250000
B27: Saturn | C27: 15 | D27: FALSE | E27: FALSE | G27: Pluto | H27: FALSE | I27: FALSE | K27: Total | L27: =SUM(COUNTIF(C40:C42,TRUE),Warframe!N6,Primary!R15,Secondary!S12,Melee!W29,Companion!M5,Companion!M9,Companion!M17,Vehicle!H5,Vehicle!H7,Vehicle!H12,Vehicle!H14,Vehicle!H16,AmpDrifter!H3)&"/"&SUM(Warframe!O7,Primary!S16,Secondary!T13,Melee!X30,Companion!N6,Companion!N10,Companion!N18,Vehicle!I6,Vehicle!I10,Vehicle!I13,Vehicle!I15,Vehicle!I17,AmpDrifter!I4,COUNTA(Vehicle!H22)) -> 474/805 | N27: TOTAL | O27: =SUM(D44,D45,Warframe!O6,Primary!S15,Secondary!T12,Melee!X29,Companion!N5,Companion!N9,Companion!N17,Vehicle!I5,Vehicle!I7,Vehicle!I12,Vehicle!I14,Vehicle!I16,AmpDrifter!I3,COUNTIF(Vehicle!H22,"TRUE"))&"/"&SUM(Warframe!O7,Primary!S16,Secondary!T13,Melee!X30,Companion!N6,Companion!N10,Companion!N18,Vehicle!I6,Vehicle!I10,Vehicle!I13,Vehicle!I15,Vehicle!I17,AmpDrifter!I4,COUNTA(Vehicle!H22)) -> 378/805 | Q27: MR11 | R27: 302500
B28: Uranus | C28: 14 | D28: FALSE | E28: FALSE | G28: Sedna | H28: FALSE | I28: FALSE | Q28: MR12 | R28: 360000
B29: Neptune | C29: 13 | D29: FALSE | E29: FALSE | G29: Eris | H29: FALSE | I29: FALSE | K29: Intrinsics | L29: =Vehicle!I19&"/"&Vehicle!I20 -> 41/50 | N29: Mastery Total | O29: =SUM(D37,E37,H30,H33,I30,J33,D44*6000,D45*3000,Warframe!O6*6000,Primary!S15*3000,Primary!S17*1000,Secondary!T12*3000,Secondary!T14*1000,Melee!X29*3000,Melee!X31*1000,Companion!N5*6000,Companion!N9*3000,Companion!N17*6000,Vehicle!I5*6000,Vehicle!I9*3000,Vehicle!I11*1000,Vehicle!I12*3000,Vehicle!I14*6000,Vehicle!I16*6000,Vehicle!I18*2000,AmpDrifter!I3*3000,AmpDrifter!I5*1500,Vehicle!H22*6000,Vehicle!I19*1500) -> 1600672 | Q29: MR13 | R29: 422500
B30: Pluto | C30: 13 | D30: FALSE | E30: FALSE | G30: Mastery | H30: =COUNTIF(H17:H29,"TRUE")*1000 -> 0 | I30: =COUNTIF(I17:I29,"TRUE")*1000 -> 0 | K30: Drifter Intrinsics | L30: =AmpDrifter!I5&"/"&AmpDrifter!I6 -> 38/40 | N30: Expected MR | O30: =LOOKUP(O29,R16:R52,Q16:Q52) -> MR25 | Q30: MR14 | R30: 490000
B31: Sedna | C31: 16 | D31: FALSE | E31: FALSE | Q31: MR15 | R31: 562000
B32: Eris | C32: 13 | D32: FALSE | E32: FALSE | G32: Solar Mastery Override | I32: Steel Path Mastery Override | Q32: MR16 | R32: 640000
B33: Kuva Fortress | C33: 8 | D33: FALSE | E33: FALSE | G33: Enter Here--> | H33: 27569 | I33: Enter Here--> | J33: 3603 | Q33: MR17 | R33: 722500
B34: Void | C34: 13 | D34: FALSE | E34: FALSE | Q34: MR18 | R34: 810000
B35: Zariman | C35: 5 | D35: FALSE | E35: FALSE | Q35: MR19 | R35: 902500
B36: Duviri | C36: 3 | D36: FALSE | E36: FALSE | Q36: MR20 | R36: 1000000
B37: Rough Mastery | D37: =SUMIF(D17:D36,"TRUE", C17:C36)*61.7053829 -> 0 | E37: =SUMIF(E17:E36,"TRUE", C17:C36)*61.7053829 -> 0 | Q37: MR21 | R37: 1102500
Q38: MR22 | R38: 1210000
B39: Founder Items | C39: Acquired | D39: Mastered | Q39: MR23 | R39: 1322500
B40: Excalibur Prime | C40: FALSE | D40: FALSE | Q40: MR24 | R40: 1440000
B41: Lato Prime | C41: FALSE | D41: FALSE | Q41: MR25 | R41: 1562500
B42: Skana Prime | C42: FALSE | D42: FALSE | Q42: MR26 | R42: 1690000
Q43: MR27 | R43: 1822500
B44: Excalibur P. Complete | D44: =COUNTIF(D40,"true") -> 0 | Q44: MR28 | R44: 1960000
B45: Other Founders Complete | D45: =COUNTIF(D41:D42,"true") -> 0 | Q45: MR29 | R45: 2102500
B46: Total Founders Items | D46: 3 | Q46: MR30 | R46: 2250000
Q47: Legendary 1 | R47: 2397500
...

Sheet Warframe
B2: Warframes | C2: Acquired | D2: Mastered | E2: Subsumed | F2: Method to Obtain | H2: Primes | I2: Acquired | J2: Mastered | K2: Method to Obtain | M2: Item | N2: Owned | O2: Completed
B3: Ash | C3: TRUE | D3: TRUE | E3: FALSE | F3: Railjack - Circuit available | H3: Ash Prime | I3: FALSE | J3: FALSE | K3: Relics | M3: Warframes | N3: =COUNTIF(C3:C66, "TRUE") -> 62 | O3: =COUNTIF(D3:D66, "TRUE") -> 60
B4: Atlas | C4: FALSE | D4: FALSE | E4: FALSE | F4: Quest: The Jordas Precept &Jordas Golem Assa. - Circuit available | H4: Atlas Prime | I4: FALSE | J4: FALSE | K4: Relics | M4: Primes | N4: =COUNTIF(I3:I51, "TRUE") -> 17 | O4: =COUNTIF(J3:J51, "TRUE") -> 13
B5: Banshee | C5: TRUE | D5: TRUE | E5: FALSE | F5: Clan:Tenno Lab | H5: Banshee Prime | I5: FALSE | J5: FALSE | K5: Relics | M5: Umbra | N5: =COUNTIF(I54, "TRUE") -> 1 | O5: =COUNTIF(J54, "TRUE") -> 1
B6: Baruuk | C6: TRUE | D6: TRUE | E6: FALSE | F6: Syndicate: Vox Solaris - Circuit available | H6: Baruuk Prime | I6: FALSE | J6: FALSE | K6: Relics | M6: Total | N6: =SUM(N3:N5) -> 80 | O6: =SUM(O3:O5) -> 74
B7: Caliban | C7: TRUE | D7: TRUE | E7: FALSE | F7: Narmer Bounties (Fortuna/Cetus) | H7: Caliban Prime | I7: FALSE | J7: FALSE | K7: Relics | M7: Total Warframes | O7: =COUNTA(D3:D66,J3:J51,J54) -> 114
B8: Chroma | C8: TRUE | D8: TRUE | E8: FALSE | F8: Quest: The New Strange & Junctions - Circuit available | H8: Chroma Prime | I8: FALSE | J8: FALSE | K8: Relics
B9: Citrine | C9: TRUE | D9: FALSE | E9: FALSE | F9: Mirror Defense: Tyana Pass Mars | H9: Ember Prime | I9: FALSE | J9: FALSE | K9: Relics
B10: Cyte-09 | C10: TRUE | D10: TRUE | E10: FALSE | F10: Quest: The Hex & Höllvania Bounties | H10: Equinox Prime | I10: FALSE | J10: FALSE | K10: Relics
B11: Dagath | C11: TRUE | D11: TRUE | E11: FALSE | F11: Clan: Dagath's Hollow | H11: Frost Prime | I11: FALSE | J11: FALSE | K11: Relics
B12: Dante | C12: TRUE | D12: TRUE | E12: FALSE | F12: Mission: Disruption (Deimos, Armatus) | H12: Gara Prime | I12: FALSE | J12: FALSE | K12: Relics
B13: Ember | C13: TRUE | D13: TRUE | E13: FALSE | F13: Boss: Gen. Sargas Ruk (Saturn) - Circuit available | H13: Garuda Prime | I13: FALSE | J13: FALSE | K13: Relics
B14: Equinox | C14: TRUE | D14: TRUE | E14: FALSE | F14: Boss: Tyl Regor (Uranus) | H14: Gauss Prime | I14: TRUE | J14: TRUE | K14: Relics
B15: Excalibur | C15: TRUE | D15: TRUE | E15: FALSE | F15: Boss: Lt. Lech Kril (Mars) - Circuit available | H15: Grendel Prime | I15: TRUE | J15: FALSE | K15: Relics
B16: Follie | C16: TRUE | D16: TRUE | E16: FALSE | F16: Mission: Follie's Hunt (Venus, Vesper Relay) | H16: Gyre Prime | I16: TRUE | J16: TRUE | K16: Relics
B17: Frost | C17: TRUE | D17: TRUE | E17: FALSE | F17: Boss: Cpt. Vor & Lt. Lech Kril (Ceres) - Circuit available | H17: Harrow Prime | I17: TRUE | J17: TRUE | K17: Relics
B18: Gara | C18: TRUE | D18: TRUE | E18: FALSE | F18: Quest: Saya's Vigil & Cetus Bounties - Circuit available | H18: Hildryn Prime | I18: FALSE | J18: FALSE | K18: Relics
B19: Garuda | C19: TRUE | D19: TRUE | E19: FALSE | F19: Quest: Vox Solaris & Fortuna Bounties - Circuit available | H19: Hydroid Prime | I19: FALSE | J19: FALSE | K19: Relics
... B51: Saryn | C51: TRUE | D51: TRUE | E51: FALSE | F51: Boss: Kela De Thaym (Sedna) - Circuit available | H51: Zephyr Prime | I51: TRUE | J51: FALSE | K51: Relics
B52: Sevagoth | C52: TRUE | D52: TRUE | E52: FALSE | F52: Quest: Call of the Tempestarii & Void Storms
B53: Styanax | C53: TRUE | D53: TRUE | E53: FALSE | F53: Kahls Garrison: Chipper inventory | H53: Umbra | I53: Acquired | J53: Maxed | K53: Method to Obtain
B54: Temple | C54: TRUE | D54: TRUE | E54: FALSE | F54: Mission: Stage Defense (Höllvania) | H54: Excalibur Umbra | I54: TRUE | J54: TRUE | K54: Quest - The Sacrifice
B55: Titania | C55: TRUE | D55: FALSE | E55: FALSE | F55: Quest: The Silver Grove - Circuit available
B56: Trinity | C56: TRUE | D56: TRUE | E56: FALSE | F56: Boss: Ambulas (Pluto) - Circuit available
B57: Uriel | C57: TRUE | D57: TRUE | E57: FALSE | F57: Quest: The Old Peace & Descendia
B58: Valkyr | C58: TRUE | D58: TRUE | E58: FALSE | F58: Boss: Alad V (Jupiter) - Circuit available
B59: Vauban | C59: TRUE | D59: TRUE | E59: FALSE | F59: Nightwave Offerings - Circuit available
B60: Volt | C60: TRUE | D60: TRUE | E60: FALSE | F60: Clan: Tenno Lab
B61: Voruna | C61: TRUE | D61: TRUE | E61: FALSE | F61: Mission: Conjunction Survival (Lua)
B62: Wisp | C62: TRUE | D62: TRUE | E62: FALSE | F62: Boss: Ropalolyst (Jupiter)
B63: Wukong | C63: TRUE | D63: TRUE | E63: FALSE | F63: Clan: Tenno Lab
B64: Xaku | C64: TRUE | D64: TRUE | E64: FALSE | F64: Quest: Heart of Deimos & Bounties (Necralisk)
B65: Yareli | C65: TRUE | D65: TRUE | E65: FALSE | F65: Quest: The Waverider & Dojo (Ventkids)
B66: Zephyr | C66: TRUE | D66: TRUE | E66: FALSE | F66: Clan: Tenno Lab

Sheet Primary
B2: Rifles | C2: Acquired | D2: Mastered | E2: Method to Obtain | G2: Shotguns | H2: Acquired | I2: Mastered | J2: Method to Obtain | L2: Launchers | M2: Acquired | N2: Mastered | O2: Method to Obtain | Q2: Item | R2: Owned | S2: Completed
B3: Acceltra | C3: TRUE | D3: TRUE | E3: Drop: Demolisher in Disruption (Uranus, Ur) | G3: Arca Plasmor | H3: TRUE | I3: FALSE | J3: Clan - Energy Lab | L3: Carmine Penta | M3: FALSE | N3: FALSE | O3: Mission - Pluto/Veil Proxima Derelicts | Q3: Rifles | R3: =COUNTIF(C3:C72, "TRUE") -> 54 | S3: =COUNTIF(D3:D72, "TRUE") -> 37
B4: Aeolak | C4: TRUE | D4: TRUE | E4: Chrysalith Bounties & Zariman Missions | G4: Astilla | H4: TRUE | I4: FALSE | J4: Market | L4: Miter | M4: TRUE | N4: TRUE | O4: Boss: Cpt. Vor & Lt. Lech Kril (Ceres) - Component for Panthera | Q4: Shotguns | R4: =COUNTIF(H3:H23, "TRUE") -> 18 | S4: =COUNTIF(I3:I23, "TRUE") -> 8
B5: Alternox | C5: TRUE | D5: TRUE | E5: Chrysalith Bounties | G5: Boar | H5: TRUE | I5: TRUE | J5: Drop - Drekar Trooper | L5: Ogris | M5: TRUE | N5: FALSE | O5: Clan - Chem Lab | Q5: Snipers | R5: =COUNTIF(H26:H35, "TRUE") -> 6 | S5: =COUNTIF(I26:I35, "TRUE") -> 4
B6: Ambassador | C6: TRUE | D6: TRUE | E6: Empyrean Survival & Raknoid drops | G6: Cedo | H6: TRUE | I6: FALSE | J6: Syndicate - Entrati | L6: Panthera | M6: TRUE | N6: FALSE | O6: Market - Uses Miter & Hikou to craft | Q6: Bows | R6: =COUNTIF(H38:H52, "TRUE") -> 13 | S6: =COUNTIF(I38:I52, "TRUE") -> 10
B7: Amprex | C7: TRUE | D7: FALSE | E7: Clan - Energy Lab | G7: Convectrix | H7: TRUE | I7: FALSE | J7: Clan - Energy Lab | L7: Penta | M7: TRUE | N7: TRUE | O7: Market | Q7: Spearguns | R7: =COUNTIF(H56:H59, "TRUE") -> 4 | S7: =COUNTIF(I56:I59, "TRUE") -> 2
B8: Argonak | C8: TRUE | D8: TRUE | E8: Clan - Chem Lab | G8: Corinth | H8: TRUE | I8: FALSE | J8: Market | L8: Secura Penta | M8: FALSE | N8: FALSE | O8: Syndicate - Perrin Sequence | Q8: Launchers | R8: =COUNTIF(M3:M13, "TRUE") -> 8 | S8: =COUNTIF(N3:N13, "TRUE") -> 3
B9: AX-52 | C9: TRUE | D9: TRUE | E9: Syndicate - The Hex | G9: Drakgoon | H9: TRUE | I9: TRUE | J9: Market - Component for Zarr | L9: Simulor | M9: FALSE | N9: FALSE | O9: Syndicate - Cephalon Simaris | Q9: Bayonet | R9: =COUNTIF(H62, "TRUE") -> 1 | S9: =COUNTIF(I62, "TRUE") -> 1
B10: Basmu | C10: TRUE | D10: TRUE | E10: Nights of Naberus - Daughter shop | G10: Exergis | H10: TRUE | I10: TRUE | J10: Market | L10: Synoid Simulor | M10: TRUE | N10: FALSE | O10: Syndicate - Cephalon Suda | Q10: Primes | R10: =COUNTIF(M16:M48, "TRUE") -> 7 | S10: =COUNTIF(N16:N48, "TRUE") -> 6
B11: Battacor | C11: TRUE | D11: FALSE | E11: Clan - Energy Lab | G11: Felarx | H11: TRUE | I11: TRUE | J11: Syndicate- The Holdfasts | L11: Tonkor | M11: TRUE | N11: FALSE | O11: Market | Q11: MK1 | R11: =COUNTIF(M51:M53, "TRUE") -> 3 | S11: =COUNTIF(N51:N53, "TRUE") -> 3
B12: Baza | C12: TRUE | D12: TRUE | E12: Clan - Tenno Lab | G12: Hek | H12: TRUE | I12: TRUE | J12: Market | L12: Torid | M12: TRUE | N12: TRUE | O12: Clan - Bio Lab | Q12: Kuva | R12: =COUNTIF(M57:M80, "TRUE") -> 1 | S12: =SUM(COUNTIF(N57, "TRUE"),COUNTIF(N59, "TRUE"),COUNTIF(N61, "TRUE"),COUNTIF(N63, "TRUE"),COUNTIF(N65, "TRUE"),COUNTIF(N67, "TRUE"),COUNTIF(N69, "TRUE"),COUNTIF(N71, "TRUE"),COUNTIF(N73, "TRUE"),COUNTIF(N75, "TRUE"), COUNTIF(N77, "TRUE"), COUNTIF(N79, "TRUE")) -> 1
B13: Boltor | C13: TRUE | D13: TRUE | E13: Market - Component for Boltace | G13: Kohm | H13: TRUE | I13: TRUE | J13: Market | L13: Zarr | M13: TRUE | N13: FALSE | O13: Market - Uses Drakgoon to craft | Q13: Tenet | R13: =COUNTIF(M83:M96, "TRUE") -> 3 | S13: =SUM(COUNTIF(N83, "TRUE"),COUNTIF(N85, "TRUE"),COUNTIF(N87, "TRUE"),COUNTIF(N89, "TRUE"),COUNTIF(N91, "TRUE"),COUNTIF(N93, "TRUE"),COUNTIF(N95, "TRUE")) -> 3
B14: Braton | C14: TRUE | D14: TRUE | E14: Market | G14: Phage | H14: TRUE | I14: FALSE | J14: Clan - Bio Lab | Q14: Coda | R14: =COUNTIF(H65:H74, "TRUE") -> 3 | S14: =SUM(COUNTIF(I65, "TRUE"),COUNTIF(I67, "TRUE"),COUNTIF(I69, "TRUE"),COUNTIF(I71, "TRUE"),COUNTIF(I73, "TRUE")) -> 2
B15: Braton Vandal | C15: FALSE | D15: FALSE | E15: Mission - Elite Sanctuary Onslaught | G15: Phantasma | H15: TRUE | I15: FALSE | J15: Market | L15: Primes | M15: Acquired | N15: Mastered | O15: Method to Obtain | Q15: Total | R15: =SUM(R3:R14) -> 121 | S15: =SUM(S3:S14) -> 80
B16: Bubonico | C16: FALSE | D16: FALSE | E16: Clan - Bio Lab | G16: Rauta | H16: FALSE | I16: FALSE | J16: Acrithis/Duviri | L16: Acceltra Prime | M16: TRUE | N16: TRUE | O16: Relics | Q16: Total Primaries | S16: =COUNTA(D3:D72,I3:I23,I26:I35,I38:I52,I56:I59,N3:N13,N16:N48,N51:N53,N57,N59,N61,N63,N65,N67,N69,N71,N73,N75,N77,N79,N83,N85,N87,N89,N91,N93,N95,I65,I67,I69,I71,I62,I73) -> 192
B17: Burston | C17: TRUE | D17: TRUE | E17: Market | G17: Sancti Tigris | H17: FALSE | I17: FALSE | J17: Syndicate - New Loka | L17: Alternox Prime | M17: TRUE | N17: TRUE | O17: Relics | Q17: Lvl 40 Primaries | S17: =SUM(COUNTIF(N84, "TRUE"),COUNTIF(N86, "TRUE"),COUNTIF(N88, "TRUE"),COUNTIF(N90, "TRUE"),COUNTIF(N92, "TRUE"),COUNTIF(N94, "TRUE"),COUNTIF(N96, "TRUE"))+SUM(COUNTIF(N58, "TRUE"),COUNTIF(N60, "TRUE"),COUNTIF(N62, "TRUE"),COUNTIF(N64, "TRUE"),COUNTIF(N66, "TRUE"),COUNTIF(N68, "TRUE"),COUNTIF(N70, "TRUE"),COUNTIF(N72, "TRUE"),COUNTIF(N74, "TRUE"),COUNTIF(N76, "TRUE"), COUNTIF(N78, "TRUE"), COUNTIF(N80, "TRUE"), COUNTIF(I66, "TRUE"), COUNTIF(I68, "TRUE"), COUNTIF(I70, "TRUE"), COUNTIF(I72, "TRUE"), COUNTIF(I74, "TRUE")) -> 6
B18: Buzlok | C18: TRUE | D18: TRUE | E18: Clan - Chem Lab | G18: Sobek | H18: TRUE | I18: FALSE | J18: Market | L18: Astilla Prime | M18: FALSE | N18: FALSE | O18: Relics | Q18: Pot Lvl 40 Primaries | S18: =SUMPRODUCT((H65:H73=TRUE)*(I66:I74=FALSE)) + SUMPRODUCT((M57:M79=TRUE)*(N58:N80=FALSE)) + SUMPRODUCT((M83:M95=TRUE)*(N84:N96=FALSE)) -> 1
B19: Dera | C19: TRUE | D19: FALSE | E19: Clan - Energy Lab | G19: Steflos | H19: TRUE | I19: FALSE | J19: Mission - Mirror Defense Tyana Pass | L19: Baza Prime | M19: FALSE | N19: FALSE | O19: Relics
B20: Dera Vandal | C20: FALSE | D20: FALSE | E20: Mission - Invasions | G20: Strun | H20: TRUE | I20: TRUE | J20: Market | L20: Boar Prime | M20: FALSE | N20: FALSE | O20: Relics
B21: Dex Sybaris | C21: TRUE | D21: TRUE | E21: Mission - Anniversary Alert | G21: Strun Wraith | H21: FALSE | I21: FALSE | J21: Mission - Invasions | L21: Boltor Prime | M21: FALSE | N21: FALSE | O21: Relics
B22: EFV-5 Jupiter | C22: TRUE | D22: FALSE | E22: Syndicate - The Hex | G22: Tigris | H22: TRUE | I22: FALSE | J22: Market | L22: Braton Prime | M22: TRUE | N22: TRUE | O22: Relics
B23: Enkaus | C23: TRUE | D23: TRUE | E23: Mission: Follie's Hunt (Venus, Vesper Relay) | G23: Vaykor Hek | H23: TRUE | I23: TRUE | J23: Syndicate - Steel Meridian | L23: Burston Prime | M23: TRUE | N23: TRUE | O23: Relics
B24: Flux Rifle | C24: TRUE | D24: FALSE | E24: Clan - Energy Lab | L24: Cernos Prime | M24: FALSE | N24: FALSE | O24: Relics (Perma-unvaulted)
B25: Fulmin | C25: TRUE | D25: TRUE | E25: Market | G25: Snipers | H25: Acquired | I25: Mastered | J25: Method to Obtain | L25: Cedo Prime | M25: TRUE | N25: TRUE | O25: Relics
B26: Glaxion | C26: TRUE | D26: FALSE | E26: Clan - Energy Lab | G26: Komorex | H26: TRUE | I26: FALSE | J26: Clan - Energy Lab | L26: Corinth Prime | M26: FALSE | N26: FALSE | O26: Relics
B27: Glaxion Vandal | C27: TRUE | D27: TRUE | E27: Baro Ki'Teer | G27: Lanka | H27: TRUE | I27: FALSE | J27: Clan - Energy Lab | L27: Daikyu Prime | M27: FALSE | N27: FALSE | O27: Relics
B28: Gorgon | C28: TRUE | D28: TRUE | E28: Drop - Heavy Gunner/Grineer Warden | G28: Perigale | H28: TRUE | I28: TRUE | J28: Mission Conjunction Survival | L28: Fulmin Prime | M28: FALSE | N28: FALSE | O28: Relics
B29: Gorgon Wraith | C29: FALSE | D29: FALSE | E29: Mission - Razorback Invasion | G29: Rubico | H29: TRUE | I29: TRUE | J29: Market | L29: Gotva Prime | M29: TRUE | N29: TRUE | O29: Baro Ki'Teer
B30: Grakata | C30: TRUE | D30: TRUE | E30: Market - Component for Twin Gratakas | G30: Snipetron | H30: FALSE | I30: FALSE | J30: Mission - ??? (Events) | L30: Latron Prime | M30: TRUE | N30: FALSE | O30: Relics
B31: Grinlok | C31: TRUE | D31: TRUE | E31: Clan - Chem Lab | G31: Snipetron Vandal | H31: FALSE | I31: FALSE | J31: Mission - Invasion | L31: Nagantaka Prime | M31: FALSE | N31: FALSE | O31: Relics
B32: Harpak | C32: TRUE | D32: TRUE | E32: Market | G32: Sporothrix | H32: FALSE | I32: FALSE | J32: Mission - Deimos Bounties | L32: Panthera Prime | M32: FALSE | N32: FALSE | O32: Relics
B33: Hema | C33: FALSE | D33: FALSE | E33: Clan - Bio Lab | G33: Vectis | H33: TRUE | I33: TRUE | J33: Market | L33: Paris Prime | M33: FALSE | N33: FALSE | O33: Relics
B34: Higasa | C34: TRUE | D34: TRUE | E34: Mission - Shrine Defense | G34: Vulkar | H34: TRUE | I34: TRUE | J34: Market | L34: Perigale Prime | M34: FALSE | N34: FALSE | O34: Relics
B35: Hind | C35: TRUE | D35: TRUE | E35: Market | G35: Vulkar Wraith | H35: FALSE | I35: FALSE | J35: Baro Ki'Teer | L35: Phantasma Prime | M35: FALSE | N35: FALSE | O35: Relics
B36: Ignis | C36: TRUE | D36: TRUE | E36: Clan - Chem Lab | L36: Rubico Prime | M36: FALSE | N36: FALSE | O36: Relics
B37: Ignis Wraith | C37: TRUE | D37: TRUE | E37: Baro Ki'Teer | G37: Bows | H37: Acquired | I37: Mastered | J37: Method to Obtain | L37: Scourge Prime | M37: FALSE | N37: FALSE | O37: Relics
B38: Karak | C38: TRUE | D38: FALSE | E38: Market | G38: Attica | H38: TRUE | I38: TRUE | J38: Clan - Tenno Lab | L38: Soma Prime | M38: FALSE | N38: FALSE | O38: Relics
B39: Karak Wraith | C39: FALSE | D39: FALSE | E39: Mission - Invasions | G39: Cernos | H39: TRUE | I39: TRUE | J39: Market - Component for Mutalist Cernos | L39: Stradavar Prime | M39: FALSE | N39: FALSE | O39: Relics
B40: Latron | C40: TRUE | D40: TRUE | E40: Market - Component for Tiberon | G40: Cinta | H40: FALSE | I40: FALSE | J40: Enigma Puzzles in Duviri Experience | L40: Strun Prime | M40: FALSE | N40: FALSE | O40: Relics
B41: Latron Wraith | C41: FALSE | D41: FALSE | E41: Mission - Invasions | G41: Daikyu | H41: TRUE | I41: TRUE | J41: Clan - Tenno Lab | L41: Sybaris Prime | M41: FALSE | N41: FALSE | O41: Relics
...

Sheet Secondary
B2: Single | C2: Acquired | D2: Mastered | E2: Method to Obtain | G2: Dual | H2: Acquired | I2: Mastered | J2: Method to Obtain | L2: Prime | M2: Acquired | N2: Mastered | O2: Method to Obtain | R2: Item | S2: Owned | T2: Completed
B3: Acrid | C3: FALSE | D3: FALSE | E3: Clan - Bio Lab | G3: Afuris | H3: TRUE | I3: TRUE | J3: Market - Uses 2 Furis to craft | L3: Afuris Prime | M3: FALSE | N3: FALSE | O3: Relics | R3: Single | S3: =COUNTIF(C3:C65, "TRUE") -> 51 | T3: =COUNTIF(D3:D65, "TRUE") -> 43
B4: Angstrum | C4: TRUE | D4: TRUE | E4: Market | G4: Akarius | H4: FALSE | I4: FALSE | J4: Drop - Demolisher Infested | L4: Akarius Prime | M4: FALSE | N4: FALSE | O4: Relics | R4: Dual | S4: =COUNTIF(H3:H27, "TRUE") -> 21 | T4: =COUNTIF(I3:I27, "TRUE") -> 13
B5: Arca Scisco | C5: TRUE | D5: TRUE | E5: Clan - Energy Lab | G5: Akbolto | H5: TRUE | I5: TRUE | J5: Market - Component for Akjagara - Uses 2 Bolto to craft | L5: Akbolto Prime | M5: FALSE | N5: FALSE | O5: Relics | R5: Thrown | S5: =COUNTIF(H30:H41, "TRUE") -> 11 | T5: =COUNTIF(I30:I41, "TRUE") -> 9
B6: Athodai | C6: TRUE | D6: TRUE | E6: Mission - Venus Proxima Derelicts | G6: Akbronco | H6: TRUE | I6: FALSE | J6: Market - Uses 2 Bronco to craft | L6: Akbronco Prime | M6: FALSE | N6: FALSE | O6: Relics - Uses 2 Bronco Prime to craft | R6: Prime | S6: =COUNTIF(M3:M31, "TRUE") -> 4 | T6: =COUNTIF(N3:N31, "TRUE") -> 4
B7: Atomos | C7: TRUE | D7: TRUE | E7: Market - Component for Twin Basolk | G7: Akjagara | H7: TRUE | I7: FALSE | J7: Market - Uses Akbolto & Dual Skana as components | L7: Akjagara Prime | M7: FALSE | N7: FALSE | O7: Relics | R7: MK1 | S7: =COUNTIF(M34:M35, "TRUE") -> 2 | T7: =COUNTIF(N34:N35, "TRUE") -> 2
B8: Azima | C8: FALSE | D8: FALSE | E8: Login Reward - 100/300/500/700 | G8: Aklato | H8: TRUE | I8: TRUE | J8: Market | L8: Aklex Prime | M8: FALSE | N8: FALSE | O8: Relics (Baro Ki'Teer) - Uses 2 Lex Prime to craft | R8: Kitgun | S8: =COUNTIF(M38:M43, "TRUE") -> 0 | T8: =COUNTIF(N38:N43, "TRUE") -> 0
B9: Ballistica | C9: TRUE | D9: TRUE | E9: Market | G9: Aklex | H9: TRUE | I9: TRUE | J9: Market - Uses 2 Lex to craft | L9: Akmagnus Prime | M9: FALSE | N9: FALSE | O9: Relics (Baro Ki'Teer) - Uses 2 Magnus Prime to craft | R9: Kuva | S9: =COUNTIF(M46:M55, "TRUE") -> 1 | T9: =SUM(COUNTIF(N46, "TRUE"),COUNTIF(N48, "TRUE"),COUNTIF(N50, "TRUE"),COUNTIF(N52, "TRUE"),COUNTIF(N54, "TRUE")) -> 1
B10: Bolto | C10: TRUE | D10: TRUE | E10: Market - Component for Akbolto & Hystrix - Use Lato to craft | G10: Akmagnus | H10: TRUE | I10: TRUE | J10: Market - Uses 2 Magnus to craft | L10: Aksomati Prime | M10: FALSE | N10: FALSE | O10: Relics | R10: Tenet | S10: =COUNTIF(M59:M68, "TRUE") -> 2 | T10: =SUM(COUNTIF(N59, "TRUE"),COUNTIF(N61, "TRUE"),COUNTIF(N63, "TRUE"),COUNTIF(N65, "TRUE"),COUNTIF(N67, "TRUE")) -> 2
B11: Brakk | C11: FALSE | D11: FALSE | E11: Drop - The Grustrag Three | G11: Aksomati | H11: TRUE | I11: FALSE | J11: Market - Uses Akstiletto to craft | L11: Akstilletto Prime | M11: FALSE | N11: FALSE | O11: Relics | R11: Coda | S11: =COUNTIF(H44:H51, "TRUE") -> 1 | T11: =SUM(COUNTIF(I44, "TRUE"),COUNTIF(I46, "TRUE"),COUNTIF(I48, "TRUE"),COUNTIF(I50, "TRUE")) -> 1
B12: Bronco | C12: TRUE | D12: TRUE | E12: Market - Component for Akbronco | G12: Akstiletto | H12: TRUE | I12: TRUE | J12: Clan: Tenno Lab - Component for Aksomati & Sarpa | L12: Akvasto Prime | M12: FALSE | N12: FALSE | O12: Relics (Baro Ki'Teer) - Uses 2 Vasto Prime to craft | R12: Total | S12: =SUM(S3:S11) -> 93 | T12: =SUM(T3:T11) -> 75
B13: Catabolyst | C13: FALSE | D13: FALSE | E13: Clan - Bio Lab | G13: Akvasto | H13: TRUE | I13: FALSE | J13: Market - Uses 2 Vasto to craft | L13: Ballistica Prime | M13: FALSE | N13: FALSE | O13: Relics | R13: Total Secondaries | T13: =COUNTA(D3:D65,I30:I41,I3:I27,N3:N31,N34:N35,N38:N43, N46,N48,N50,N52,N54,N59,N61,N63,N65,N67,I44,I46,I48,I50) -> 151
B14: Cestra | C14: TRUE | D14: TRUE | E14: Market - Component for Dual Cestra | G14: Akzani | H14: TRUE | I14: TRUE | J14: Market | L14: Bronco Prime | M14: FALSE | N14: FALSE | O14: Relics - Component for Akbronco Prime | R14: Lvl 40 Secondaries | T14: =SUM(COUNTIF(N47, "TRUE"),COUNTIF(N49, "TRUE"),COUNTIF(N51, "TRUE"),COUNTIF(N53, "TRUE"),COUNTIF(N55, "TRUE"),COUNTIF(N60, "TRUE"),COUNTIF(N62, "TRUE"),COUNTIF(N64, "TRUE"),COUNTIF(N66, "TRUE"),COUNTIF(N68, "TRUE"),COUNTIF(I45, "TRUE"),COUNTIF(I47, "TRUE"),COUNTIF(I49, "TRUE"),COUNTIF(I51, "TRUE")) -> 3
B15: Cyanex | C15: TRUE | D15: TRUE | E15: Clan - Energy Lab | G15: Dex Furis | H15: TRUE | I15: TRUE | J15: Mission - Anniversary Alert | L15: Epitaph Prime | M15: TRUE | N15: TRUE | O15: Relics | R15: Pot Lvl 40 Secondaries | T15: =SUMPRODUCT((H44:H50=TRUE)*(I45:I51=FALSE)) + SUMPRODUCT((M46:M54=TRUE)*(N47:N55=FALSE)) + SUMPRODUCT((M59:M67=TRUE)*(N60:N68=FALSE)) -> 1
B16: Cycron | C16: TRUE | D16: TRUE | E16: Clan - Energy Lab | G16: Dual Cestra | H16: TRUE | I16: TRUE | J16: Clan: Energy Lab - Uses 2 Cestra to craft | L16: Euphona Prime | M16: FALSE | N16: FALSE | O16: Relics
B17: Detron | C17: FALSE | D17: FALSE | E17: Drop - Zanuka Hunter | G17: Dual Toxocyst | H17: TRUE | I17: TRUE | J17: Clan - Bio Lab | L17: Hikou Prime | M17: FALSE | N17: FALSE | O17: Relics (Perma-unvaulted)
B18: EFV-8 Mars | C18: TRUE | D18: FALSE | E18: Syndicate - The Hex | G18: Prisma Twin Gremlins | H18: FALSE | I18: FALSE | J18: Baro Ki'Teer | L18: Hystrix Prime | M18: FALSE | N18: FALSE | O18: Relics
B19: Embolist | C19: FALSE | D19: FALSE | E19: Clan - Bio Lab | G19: Secura Dual Cestra | H19: FALSE | I19: FALSE | J19: Syndicate - Perrin Sequence | L19: Kompressa Prime | M19: TRUE | N19: TRUE | O19: Relics
B20: Epitaph | C20: FALSE | D20: FALSE | E20: Mission - Void Storm | G20: Staticor | H20: TRUE | I20: TRUE | J20: Clan - Energy Lab | L20: Knell Prime | M20: FALSE | N20: FALSE | O20: Relics
B21: Furis | C21: TRUE | D21: TRUE | E21: Market - Component for Akfuris | G21: Telos Akbolto | H21: TRUE | I21: FALSE | J21: Syndicate - Arbiters of Hexis | L21: Lex Prime | M21: FALSE | N21: FALSE | O21: Relics (Perma-unvaulted & Baro Ki'Teer) - Component for Aklex Prime
B22: Gammacor | C22: TRUE | D22: TRUE | E22: Market - Component for Heliocor | G22: Twin Grakatas | H22: TRUE | I22: FALSE | J22: Market - Uses 2 Grataka to craft | L22: Magnus Prime | M22: FALSE | N22: FALSE | O22: Relics (Baro Ki'Teer) - Component for Akmagnus Prime
B23: Grimoire | C23: TRUE | D23: TRUE | E23: Quest- Whispers in The Walls | G23: Twin Gremlins | H23: TRUE | I23: TRUE | J23: Boss: Cpt. Vor & Lt. Lech Kril (Ceres) | L23: Pandero Prime | M23: FALSE | N23: FALSE | O23: Relics
B24: Hystrix | C24: TRUE | D24: TRUE | E24: Market - Uses Bolto & Viper to craft | G24: Twin Kohmak | H24: TRUE | I24: FALSE | J24: Boss: Kela de Thaym (Sedna) - Uses 2 Kohmak to craft | L24: Pyrana Prime | M24: TRUE | N24: TRUE | O24: Relics
B25: Knell | C25: TRUE | D25: TRUE | E25: Market | G25: Twin Rogga | H25: TRUE | I25: TRUE | J25: Market | L25: Sagek Prime | M25: FALSE | N25: FALSE | O25: Mission - The Perita Rebellion
B26: Kohmak | C26: TRUE | D26: TRUE | E26: Clan: Chem Lab - Component for Twin Kohmak | G26: Twin Vipers | H26: TRUE | I26: FALSE | J26: Market - Uses 2 Viper to craft | L26: Sicarus Prime | M26: TRUE | N26: TRUE | O26: Relics
B27: Kompressa | C27: FALSE | D27: FALSE | E27: Syndicate - Vent Kids | G27: Twin Vipers Wraith | H27: FALSE | I27: FALSE | J27: Mission - Invasions | L27: Spira Prime | M27: FALSE | N27: FALSE | O27: Relics
B28: Kraken | C28: TRUE | D28: TRUE | E28: Market - Component for Kulstar | L28: Vasto Prime | M28: FALSE | N28: FALSE | O28: Relics (Baro Ki'Teer) - Component for Akvasto Prime
B29: Kulstar | C29: TRUE | D29: FALSE | E29: Market - Uses Kraken to craft | G29: Thrown | H29: Acquired | I29: Mastered | J29: Method to Obtain | L29: Velox Prime | M29: FALSE | N29: FALSE | O29: Relics
B30: Laetum | C30: TRUE | D30: TRUE | E30: Syndicate - The Holdfasts | G30: Aegrit | H30: TRUE | I30: FALSE | J30: Syndicate - Kahls Garrison | L30: Zakti Prime | M30: FALSE | N30: FALSE | O30: Relics
B31: Lato | C31: TRUE | D31: TRUE | E31: Market - Component for Bolto | G31: Cantare | H31: TRUE | I31: TRUE | J31: Mission - Ascension | L31: Zylok Prime | M31: FALSE | N31: FALSE | O31: Relics
B32: Lato Vandal | C32: FALSE | D32: FALSE | E32: Mission - Elite Sanctuary Onslaught | G32: Castanas | H32: TRUE | I32: TRUE | J32: Clan - Tenno Lab
B33: Lex | C33: TRUE | D33: TRUE | E33: Market - Component for Aklex | G33: Despair | H33: TRUE | I33: TRUE | J33: Drop - Stalker | L33: MK1 | M33: Acquired | N33: Mastered | O33: Method to Obtain
B34: Magnus | C34: TRUE | D34: TRUE | E34: Market - Component for Akmagnus | G34: Fusilai | H34: TRUE | I34: TRUE | J34: Market | L34: MK1-Furis | M34: TRUE | N34: TRUE | O34: Market
B35: Mara Detron | C35: FALSE | D35: FALSE | E35: Baro Ki'Teer | G35: Hikou | H35: TRUE | I35: TRUE | J35: Market - Component for the Panthera | L35: MK1-Kunai | M35: TRUE | N35: TRUE | O35: Market | S35: Syndicate- The Holdfasts
B36: Marelok | C36: TRUE | D36: TRUE | E36: Clan - Chem Lab | G36: Kunai | H36: TRUE | I36: TRUE | J36: Market - Component for the Tipedo
B37: Nukor | C37: TRUE | D37: TRUE | E37: Clan - Chem Lab | G37: Pox | H37: TRUE | I37: TRUE | J37: Clan - Bio Lab | L37: Kitgun | M37: Acquired | N37: Mastered | O37: Method to Obtain
B38: Ocucor | C38: TRUE | D38: TRUE | E38: Clan - Energy Lab | G38: Sancti Castanas | H38: FALSE | I38: FALSE | J38: Syndicate - New Loka | L38: Catchmoon | M38: FALSE | N38: FALSE | O38: Syndicate - Solaris United
B39: Onos | C39: TRUE | D39: TRUE | E39: Mission - Disruption Armatus | G39: Scyotid | H39: TRUE | I39: FALSE | J39: Mission - Isleweaver | L39: Gaze | M39: FALSE | N39: FALSE | O39: Syndicate - Solaris United
B40: Pandero | C40: TRUE | D40: FALSE | E40: Market | G40: Spira | H40: TRUE | I40: TRUE | J40: Market | L40: Rattleguts | M40: FALSE | N40: FALSE | O40: Syndicate - Solaris United
B41: Plinx | C41: TRUE | D41: TRUE | E41: Market | G41: Talons | H41: TRUE | I41: TRUE | J41: Clan - Tenno Lab | L41: Sporelacer | M41: FALSE | N41: FALSE | O41: Syndicate - Entrati
...

Sheet Melee
B2: Swords/Nikanas | C2: Acquired | D2: Mastered | E2: Method to Obtain | G2: Daggers | H2: Acquired | I2: Mastered | J2: Method to Obtain | L2: Polearm/Staff | M2: Acquired | N2: Mastered | O2: Method to Obtain | Q2: Scythe | R2: Acquired | S2: Mastered | T2: Method to Obtain | V2: Item | W2: Owned | X2: Completed
B3: Azothane | C3: FALSE | D3: FALSE | E3: Syndicate - Teshins Cave | G3: Ceramic Dagger | H3: TRUE | I3: TRUE | J3: Nightwave Cred Offerings | L3: Amanata | M3: TRUE | N3: TRUE | O3: Mission - Shrine Defense | Q3: Anku | R3: TRUE | S3: TRUE | T3: Clan - Tenno Lab | V3: =B2 -> Swords/Nikanas | W3: =COUNTIF(C3:C23, "TRUE") -> 14 | X3: =COUNTIF(D3:D23, "TRUE") -> 14
B4: Broken War | C4: TRUE | D4: TRUE | E4: Quest: The Second Dream - Component for War | G4: Dark Dagger | H4: FALSE | I4: FALSE | J4: Nightwave Cred Offerings | L4: Amphis | M4: TRUE | N4: TRUE | O4: Market - Component for Sydon | Q4: Caustacyst | R4: FALSE | S4: FALSE | T4: Clan - Bio Lab | V4: =B25 -> Dual Swords | W4: =COUNTIF(C26:C40, "TRUE") -> 13 | X4: =COUNTIF(D26:D40, "TRUE") -> 10
B5: Cronus | C5: TRUE | D5: TRUE | E5: Drop - Captain Vor (Mercury) | G5: Heat Dagger | H5: TRUE | I5: FALSE | J5: Nightwave Cred Offerings | L5: Bo | M5: TRUE | N5: TRUE | O5: Market - Component for Cadus & Tipedo | Q5: Ether Reaper | R5: TRUE | S5: TRUE | T5: Market | V5: =B42 -> Heavy Blades | W5: =COUNTIF(C43:C47, "TRUE")+COUNTIF(C49:C53, "TRUE") -> 6 | X5: =COUNTIF(D43:D47, "TRUE")+COUNTIF(D49:D53, "TRUE") -> 6
B6: Dark Sword | C6: FALSE | D6: FALSE | E6: Nightwave Cred Offerings | G6: Innodem | H6: FALSE | I6: FALSE | J6: Syndicate - The Holdfasts | L6: Broken Scepter | M6: TRUE | N6: TRUE | O6: Quest - The War Within | Q6: Harmony | R6: TRUE | S6: FALSE | T6: Mission - Ascension | V6: =B55 -> Zaw | W6: =COUNTIF(C56:C66, "TRUE") -> 0 | X6: =COUNTIF(D56:D66, "TRUE") -> 0
B7: Dex Nikana | C7: TRUE | D7: TRUE | E7: Mission - Anniversary Alert | G7: Karyst | H7: TRUE | I7: TRUE | J7: Market | L7: Cadus | M7: TRUE | N7: TRUE | O7: Market - Uses Bo to craft | Q7: Hate | R7: TRUE | S7: TRUE | T7: Drop - Stalker | V7: =G2 -> Daggers | W7: =COUNTIF(H3:H10, "TRUE") -> 5 | X7: =COUNTIF(I3:I10, "TRUE") -> 4
B8: Dragon Nikana | C8: TRUE | D8: TRUE | E8: Market - Uses Nikana to craft | G8: Rakta Dark Dagger | H8: TRUE | I8: TRUE | J8: Syndicate - Red Veil | L8: Cassowar | M8: TRUE | N8: TRUE | O8: Clan - Tenno Lab | Q8: Venato | R8: FALSE | S8: FALSE | T8: Clan - Tenno Lab | V8: =G12 -> Dual Daggers | W8: =COUNTIF(H13:H16, "TRUE") -> 3 | X8: =COUNTIF(I13:I16, "TRUE") -> 3
B9: Ether Sword | C9: TRUE | D9: TRUE | E9: Market | G9: Rumblejack | H9: TRUE | I9: TRUE | J9: Quest- The new war | L9: Edun | M9: FALSE | N9: FALSE | O9: Syndicate - Teshins Cave | V9: =G18 -> Machetes | W9: =COUNTIF(H19:H28, "TRUE") -> 8 | X9: =COUNTIF(I19:I28, "TRUE") -> 6
B10: Heat Sword | C10: TRUE | D10: TRUE | E10: Nightwave Cred Offerings | G10: Sheev | H10: FALSE | I10: FALSE | J10: Mission - Invasions | L10: Guandao | M10: TRUE | N10: TRUE | O10: Clan - Tenno Lab | Q10: Hammer | R10: Acquired | S10: Mastered | T10: Method to Obtain | V10: =G30 -> Fist/Sparring | W10: =COUNTIF(H31:H40, "TRUE") -> 7 | X10: =COUNTIF(I31:I40, "TRUE") -> 6
B11: Jaw Sword | C11: FALSE | D11: FALSE | E11: Nightwave Cred Offerings | L11: Kesheg | M11: TRUE | N11: TRUE | O11: Clan - Chem Lab | Q11: Arca Titron | R11: TRUE | S11: TRUE | T11: Market | V11: =G42 -> Sword-Shield | W11: =COUNTIF(H43:H48, "TRUE") -> 4 | X11: =COUNTIF(I43:I48, "TRUE") -> 3
B12: Krohkur | C12: TRUE | D12: TRUE | E12: Market - Component for Twin Krohkur | G12: Dual Daggers | H12: Acquired | I12: Mastered | J12: Method to Obtain | L12: Korumm | M12: FALSE | N12: FALSE | O12: Mission- Narmer Bounty | Q12: Ekhein | R12: FALSE | S12: FALSE | T12: Syndicate - Cavia | V12: =G50 -> Gunblade | W12: =COUNTIF(H51:H54, "TRUE") -> 3 | X12: =COUNTIF(I51:I54, "TRUE") -> 1
B13: Mire | C13: TRUE | D13: TRUE | E13: Market | G13: Ether Daggers | H13: TRUE | I13: TRUE | J13: Quest - Stolen Dreams | L13: Lesion | M13: TRUE | N13: FALSE | O13: Market - Uses Tipedo to craft | Q13: Fragor | R13: TRUE | S13: TRUE | T13: Market | V13: =G56 -> Warfans | W13: =COUNTIF(H57:H60, "TRUE") -> 2 | X13: =COUNTIF(I57:I60, "TRUE") -> 1
B14: Nikana | C14: TRUE | D14: TRUE | E14: Clan: Tenno Lab - Component for Dragon Nikana | G14: Fang | H14: TRUE | I14: TRUE | J14: Market | L14: Orthos | M14: TRUE | N14: TRUE | O14: Market | Q14: Heliocor | R14: FALSE | S14: FALSE | T14: Syndicate: Cephalon Simaris - Use Gammacor to craft | V14: =L2 -> Polearm/Staff | W14: =COUNTIF(M3:M20, "TRUE") -> 15 | X14: =COUNTIF(N3:N20, "TRUE") -> 14
B15: Pangolin Sword | C15: FALSE | D15: FALSE | E15: Nightwave Cred Offerings | G15: Nepheri | H15: FALSE | I15: FALSE | J15: Mission- Narmer Bounty | L15: Pupacyst | M15: FALSE | N15: FALSE | O15: Clan - Bio Lab | Q15: Jat Kittag | R15: TRUE | S15: TRUE | T15: Clan - Chem Lab | V15: =L22 -> Whip/B. Whip | W15: =COUNTIF(M23:M34, "TRUE") -> 8 | X15: =COUNTIF(N23:N34, "TRUE") -> 4
B16: Pennant | C16: FALSE | D16: FALSE | E16: Drop - Grineer Railjack Captain/Commanders | G16: Okina | H16: TRUE | I16: TRUE | J16: Clan - Tenno Lab | L16: Serro | M16: TRUE | N16: TRUE | O16: Clan - Energy Lab | Q16: Magistar | R16: TRUE | S16: TRUE | T16: Market - Component for Sibear | V16: =L36 -> Glaive | W16: =COUNTIF(M37:M45, "TRUE") -> 5 | X16: =COUNTIF(N37:N45, "TRUE") -> 4
B17: Plasma Sword | C17: TRUE | D17: TRUE | E17: Nightwave Cred Offerings | L17: Sydon | M17: TRUE | N17: TRUE | O17: Clan: Chem Lab - Uses Amphis to craft | Q17: Sampotes | R17: FALSE | S17: FALSE | T17: Syndicate - Teshins Cave | V17: =L47 -> Tonfa/Nunchaku | W17: =COUNTIF(M48:M57, "TRUE") -> 8 | X17: =COUNTIF(N48:N57, "TRUE") -> 6
B18: Prisma Skana | C18: FALSE | D18: FALSE | E18: Baro Ki'Teer | G18: Machetes | H18: Acquired | I18: Mastered | J18: Method to Obtain | L18: Tipedo | M18: TRUE | N18: TRUE | O18: Market - Uses Bo & Kunai to craft - Component for Lesion | Q18: Sancti Magistar | R18: FALSE | S18: FALSE | T18: Syndicate - New Loka | V18: =L59 -> MK1 | W18: =COUNTIF(M60:M61, "TRUE") -> 2 | X18: =COUNTIF(N60:N61, "TRUE") -> 2
B19: Skana | C19: TRUE | D19: TRUE | E19: Market | G19: Gazal Machete | H19: TRUE | I19: TRUE | J19: Clan - Tenno Lab | L19: Tonbo | M19: TRUE | N19: TRUE | O19: Clan - Tenno Lab | Q19: Sibear | R19: FALSE | S19: FALSE | T19: Market - Uses Magistar to craft | V19: =Q2 -> Scythe | W19: =COUNTIF(R3:R8, "TRUE") -> 4 | X19: =COUNTIF(S3:S8, "TRUE") -> 3
B20: Skiajati | C20: TRUE | D20: TRUE | E20: Quest - The Sacrifice | G20: Kama | H20: TRUE | I20: TRUE | J20: Market - Component for Dual Kamas | L20: Vaykor Sydon | M20: TRUE | N20: TRUE | O20: Syndicate - Steel Meridian | Q20: Synoid Heliocor | R20: FALSE | S20: FALSE | T20: Syndicate - Cephalon Suda | V20: =Q10 -> Hammer | W20: =COUNTIF(R11:R22, "TRUE") -> 5 | X20: =COUNTIF(S11:S22, "TRUE") -> 5
B21: Sun & Moon | C21: TRUE | D21: TRUE | E21: Quest - The Duviri Paradox | G21: Kreska | H21: TRUE | I21: FALSE | J21: Clan - Energy Lab | Q21: Volnus | R21: TRUE | S21: TRUE | T21: Market | V21: =Q24 -> Rapier | W21: =COUNTIF(R25:R26, "TRUE") -> 2 | X21: =COUNTIF(S25:S26, "TRUE") -> 2
B22: Syam | C22: FALSE | D22: FALSE | E22: Syndicate - Teshins Cave | G22: Machete | H22: FALSE | I22: FALSE | J22: Login Reward (Random) | L22: Whip/B. Whip | M22: Acquired | N22: Mastered | O22: Method to Obtain | Q22: Wolf Sledge | R22: FALSE | S22: FALSE | T22: Drop - Wolf of Saturn Six | V22: =Q28 -> Claws | W22: =COUNTIF(R29:R31, "TRUE") -> 3 | X22: =COUNTIF(S29:S31, "TRUE") -> 2
B23: Tatsu | C23: TRUE | D23: TRUE | E23: Market | G23: Machete Wraith | H23: TRUE | I23: TRUE | J23: Baro Ki'Teer | L23: Atterax | M23: TRUE | N23: TRUE | O23: Market | V23: =Q33 -> Prime | W23: =COUNTIF(R34:R72, "TRUE") -> 2 | X23: =COUNTIF(S34:S72, "TRUE") -> 2
G24: Nami Solo | H24: TRUE | I24: TRUE | J24: Market | L24: Ceti Lacera | M24: TRUE | N24: TRUE | O24: Mission - Orphix? | Q24: Rapier | R24: Acquired | S24: Mastered | T24: Method to Obtain | V24: Assault Saw | W24: =COUNTIF(H63, "TRUE") -> 0 | X24: =COUNTIF(I63, "TRUE") -> 0
B25: Dual Swords | C25: Acquired | D25: Mastered | E25: Method to Obtain | G25: Prisma Machete | H25: TRUE | I25: TRUE | J25: Baro Ki'Teer | L25: Dorrclave | M25: TRUE | N25: FALSE | O25: Dagaths Hollow- Clan Dojo | Q25: Destreza | R25: TRUE | S25: TRUE | T25: Market | V25: =G65 -> Heavy Scythes | W25: =COUNTIF(H66:H68, "TRUE") -> 2 | X25: =COUNTIF(I66:I68, "TRUE") -> 1
B26: Dex Dakra | C26: TRUE | D26: TRUE | E26: Mission - Anniversary Alert | G26: Prova | H26: TRUE | I26: TRUE | J26: Clan - Energy Lab | L26: Galvacord | M26: TRUE | N26: FALSE | O26: Market | Q26: Endura | R26: TRUE | S26: TRUE | T26: Clan - Tenno Lab | V26: Kuva | W26: =SUM(COUNTIF(R75, "TRUE"),COUNTIF(R77, "TRUE")) -> 0 | X26: =SUM(COUNTIF(S75, "TRUE"),COUNTIF(S77, "TRUE")) -> 0
B27: Dual Cleavers | C27: TRUE | D27: TRUE | E27: Market - Component for Ripkas | G27: Prova Vandal | H27: FALSE | I27: FALSE | J27: Baro Ki'Teer | L27: Jat Kusar | M27: TRUE | N27: FALSE | O27: Clan - Chem Lab | V27: Tenet | W27: =COUNTIF(R81:R88, "TRUE") -> 0 | X27: =SUM(COUNTIF(S81, "TRUE"),COUNTIF(S83, "TRUE"),COUNTIF(S85, "TRUE"),COUNTIF(S87, "TRUE")) -> 0
B28: Dual Ether | C28: TRUE | D28: TRUE | E28: Market | G28: Slaytra | H28: TRUE | I28: FALSE | J28: Syndicate - Kahls Garrison | L28: Lacera | M28: TRUE | N28: TRUE | O28: Clan - Tenno Lab | Q28: Claws | R28: Acquired | S28: Mastered | T28: Method to Obtain | V28: Coda | W28: =COUNTIF(M64:M73, "TRUE") -> 0 | X28: =SUM(COUNTIF(N64, "TRUE"),COUNTIF(N66, "TRUE"),COUNTIF(N68, "TRUE"),COUNTIF(N70, "TRUE"),COUNTIF(N72, "TRUE")) -> 0
B29: Dual Heat Swords | C29: TRUE | D29: TRUE | E29: Market | L29: Lecta | M29: TRUE | N29: TRUE | O29: Market | Q29: Ripkas | R29: TRUE | S29: TRUE | T29: Market - Uses Ankyros & Dual Cleavers to craft | V29: Total | W29: =SUM(W3:W28) -> 121 | X29: =SUM(X3:X28) -> 99
B30: Dual Ichor | C30: FALSE | D30: FALSE | E30: Clan - Bio Lab | G30: Fist/Sparring | H30: Acquired | I30: Mastered | J30: Method to Obtain | L30: Mios | M30: FALSE | N30: FALSE | O30: Clan - Bio Lab | Q30: Venka | R30: TRUE | S30: TRUE | T30: Clan - Tenno Lab | V30: Total Melee | X30: =COUNTA(D3:D23,D26:D40,D43:D47,D49:D53,D56:D66,I3:I10,I13:I16,I19:I28,I31:I40,I43:I48,I51:I54,I57:I60,I63,I66:I68,N3:N20,N23:N34,N37:N45,N48:N57,N60:N61,S3:S8,S11:S22,S25:S26,S29:S31,S34:S72,S75, S77,S81,S83,S85,S87,N64,N66,N68,N70,N72) -> 231
B31: Dual Kamas | C31: TRUE | D31: TRUE | E31: Market - Uses 2 Kama to craft - Component for Dual Raza | G31: Ankyros | H31: TRUE | I31: TRUE | J31: Market - Component for Tekko & Ripkas | L31: Scoliac | M31: FALSE | N31: FALSE | O31: Clan - Bio Lab | Q31: Keratinos | R31: TRUE | S31: FALSE | T31: Syndicate - Entrati | V31: Lvl 40 Melee | X31: =SUM(COUNTIF(D48, "TRUE"),COUNTIF(S76, "TRUE"),COUNTIF(S78, "TRUE"),COUNTIF(S82, "TRUE"),COUNTIF(S84, "TRUE"),COUNTIF(S86, "TRUE"),COUNTIF(S88, "TRUE"),COUNTIF(N65, "TRUE"),COUNTIF(N67, "TRUE"),COUNTIF(N69, "TRUE"),COUNTIF(N71, "TRUE"),COUNTIF(N73, "TRUE")) -> 0
B32: Dual Keres | C32: TRUE | D32: FALSE | E32: Market | G32: Furax | H32: TRUE | I32: TRUE | J32: Market - Component for Knux | L32: Secura Lecta | M32: FALSE | N32: FALSE | O32: Syndicate - Perrin Sequence | V32: Pot Lvl 40 Melee | X32: =SUMPRODUCT((M64:M72=TRUE)*(N65:N73=FALSE)) + SUMPRODUCT((R75:R77=TRUE)*(S76:S78=FALSE)) + SUMPRODUCT((R81:R87=TRUE)*(S82:S88=FALSE)) + (C47=TRUE)*(D48=FALSE) -> 0
B33: Dual Raza | C33: TRUE | D33: FALSE | E33: Clan: Tenno Lab - Uses Dual Kamas to craft | G33: Furax Wraith | H33: FALSE | I33: FALSE | J33: Mission - Cetus Bounty | L33: Spinnerex | M33: TRUE | N33: FALSE | O33: Mission - Isleweaver | Q33: Prime | R33: Acquired | S33: Mastered | T33: Method to Obtain
B34: Dual Skana | C34: TRUE | D34: TRUE | E34: Market - Component for Akjagara, Dark Split-Sword & Redeemer | G34: Hirudo | H34: TRUE | I34: TRUE | J34: Market - Uses Kogake to craft | L34: Verdilac | M34: FALSE | N34: FALSE | O34: Mission - Narmer Bounties | Q34: Ankyros Prime | R34: FALSE | S34: FALSE | T34: Relics
B35: Dual Viciss | C35: TRUE | D35: FALSE | E35: Syndicate - The Hex | G35: Kogake | H35: TRUE | I35: TRUE | J35: Market - Component for Hirudo | Q35: Bo Prime | R35: FALSE | S35: FALSE | T35: Relics
B36: Dual Zoren | C36: TRUE | D36: TRUE | E36: Market - Component for Twin Basolk | G36: Korrudo | H36: FALSE | I36: FALSE | J36: Drop - Tusk Thumpers | L36: Glaive | M36: Acquired | N36: Mastered | O36: Method to Obtain | Q36: Cobra & Crane Prime | R36: FALSE | S36: FALSE | T36: Relics
B37: Nami Skyla | C37: TRUE | D37: TRUE | E37: Clan - Tenno Lab | G37: Obex | H37: TRUE | I37: TRUE | J37: Market | L37: Cerata | M37: FALSE | N37: FALSE | O37: Clan - Bio Lab | Q37: Dakra Prime | R37: FALSE | S37: FALSE | T37: Relics
B38: Prisma Dual Cleavers | C38: FALSE | D38: FALSE | E38: Baro Ki'Teer | G38: Prisma Obex | H38: FALSE | I38: FALSE | J38: Baro Ki'Teer | L38: Falcor | M38: TRUE | N38: TRUE | O38: Clan - Energy Lab | Q38: Destreza Prime | R38: FALSE | S38: FALSE | T38: Relics
B39: Twin Basolk | C39: TRUE | D39: TRUE | E39: Market - Uses Dual Zoren & Atomos to craft | G39: Ruvox | H39: TRUE | I39: FALSE | J39: Mission - Disruption (Deimos, Armatus) | L39: Glaive | M39: FALSE | N39: FALSE | O39: Nightwave Cred Offerings | Q39: Dual Kamas Prime | R39: FALSE | S39: FALSE | T39: Relics
B40: Twin Krohkur | C40: TRUE | D40: TRUE | E40: Clan: Chem Lab - Uses 2 Krohkur to craft | G40: Tekko | H40: TRUE | I40: TRUE | J40: Market - Uses Ankyros to craft | L40: Halikar | M40: TRUE | N40: TRUE | O40: Market | Q40: Dual Keres Prime | R40: FALSE | S40: FALSE | T40: Relics
L41: Halikar Wraith | M41: FALSE | N41: FALSE | O41: Baro Ki'Teer | Q41: Dual Zoren Prime | R41: FALSE | S41: FALSE | T41: Relics
...

Sheet Companion
A1: rip t
B2: Sentinels | C2: Acquired | D2: Mastered | E2: Method to Obtain | G2: Kubrows | H2: Acquired | I2: Mastered | J2: Method to Obtain | L2: Item | M2: Owned | N2: Completed
B3: Carrier | C3: TRUE | D3: TRUE | E3: Market | G3: Chesa | H3: FALSE | I3: FALSE | J3: Egg Incubation | L3: =B2 -> Sentinels | M3: =COUNTIF(C3:C13, "TRUE") -> 9 | N3: =COUNTIF(D3:D13, "TRUE") -> 9
B4: Dethcube | C4: TRUE | D4: TRUE | E4: Market | G4: Huras | H4: FALSE | I4: FALSE | J4: Egg Incubation | L4: =B35 -> Prime Sentinels | M4: =COUNTIF(C36:C41, "TRUE") -> 1 | N4: =COUNTIF(D36:D41, "TRUE") -> 1
B5: Diriga | C5: TRUE | D5: TRUE | E5: Market | G5: Raksa | H5: TRUE | I5: TRUE | J5: Egg Incubation | L5: Total | M5: =SUM(M3:M4) -> 10 | N5: =SUM(N3:N4) -> 10
B6: Djinn | C6: TRUE | D6: TRUE | E6: Clan - Bio Lab | G6: Sahasa | H6: FALSE | I6: FALSE | J6: Egg Incubation | L6: Total Sentinels | M6: =COUNTA(C3:C13,C36:C41) -> 17 | N6: =COUNTA(D3:D13,D36:D41) -> 17
B7: Helios | C7: TRUE | D7: TRUE | E7: Clan - Energy Lab | G7: Sunika | H7: FALSE | I7: FALSE | J7: Egg Incubation | L7: =B15 -> Robotic Weapons | M7: =COUNTIF(C16:C33, "TRUE") -> 16 | N7: =COUNTIF(D16:D33, "TRUE") -> 13
B8: Nautilus | C8: FALSE | D8: FALSE | E8: Mission - Neptune Proxima | G8: Helminth | H8: TRUE | I8: TRUE | J8: Nidus' Cyst Incubation | L8: =B43 -> Prime R. Weapons | M8: =COUNTIF(C44:C49, "TRUE") -> 1 | N8: =COUNTIF(D44:D49, "TRUE") -> 1
B9: Oxylus | C9: TRUE | D9: TRUE | E9: Syndicate - Solaris United | L9: Total Completed | M9: =SUM(M7:M8) -> 17 | N9: =SUM(N7:N8) -> 14
B10: Prisma Shade | C10: FALSE | D10: FALSE | E10: Baro Ki'Teer | G10: Kavats | H10: Acquired | I10: Mastered | J10: Method to Obtain | L10: Total Weapons | M10: =COUNTA(C16:C33,C44:C49) -> 24 | N10: =COUNTA(D16:D33,D44:D49) -> 24
B11: Shade | C11: TRUE | D11: TRUE | E11: Market | G11: Adarza | H11: TRUE | I11: TRUE | J11: Kavat DNA Incubation | L11: =G2 -> Kubrows | M11: =COUNTIF(H3:H8, "TRUE") -> 2 | N11: =COUNTIF(I3:I8, "TRUE") -> 2
B12: Taxon | C12: TRUE | D12: TRUE | E12: Market | G12: Smeeta | H12: FALSE | I12: FALSE | J12: Kavat DNA Incubation | L12: =G10 -> Kavats | M12: =COUNTIF(H11:H15, "TRUE") -> 2 | N12: =COUNTIF(I11:I15, "TRUE") -> 2
B13: Wyrm | C13: TRUE | D13: TRUE | E13: Market | G13: Vasca | H13: FALSE | I13: FALSE | J13: Infect your kavat with Vasca virus | L13: Moas | M13: =COUNTIF(H18:H21, "TRUE") -> 1 | N13: =COUNTIF(I18:I21, "TRUE") -> 1
G14: Venari | H14: TRUE | I14: TRUE | J14: Comes w/ Khora | L14: Predasites | M14: =COUNTIF(H24:H26, "TRUE") -> 3 | N14: =COUNTIF(I24:I26, "TRUE") -> 3
B15: Robotic Weapons | C15: Acquired | D15: Mastered | E15: Method to Obtain | G15: Venari Prime | H15: FALSE | I15: FALSE | J15: Comes w/ Khora Prime | L15: Vulpaphyla | M15: =COUNTIF(H29:H31, "TRUE") -> 3 | N15: =COUNTIF(I29:I31, "TRUE") -> 3
B16: Akaten | C16: TRUE | D16: TRUE | E16: Comes w/ Hec Hound | L16: Hounds | M16: =COUNTIF(H34:H36, "TRUE") -> 1 | N16: =COUNTIF(I34:I36, "TRUE") -> 1
B17: Artax | C17: TRUE | D17: TRUE | E17: Comes w/ Taxon | G17: Moas | H17: Acquired | I17: Mastered | J17: Method to Obtain | L17: Total | M17: =SUM(M11:M16) -> 12 | N17: =SUM(N11:N16) -> 12
B18: Batoten | C18: TRUE | D18: TRUE | E18: Comes w/ Dorma Hound | G18: Lambeo | H18: FALSE | I18: FALSE | J18: Syndicate - Solaris United | L18: Total Companions | M18: =COUNTA(H3:H8,H11:H15,H18:H21,H24:H26,H29:H31,H34:H36) -> 24 | N18: =COUNTA(I3:I8,I11:I15,I18:I21,I24:I26,I29:I31,I34:I36) -> 24
B19: Burst Laser | C19: TRUE | D19: TRUE | E19: Comes w/ Shade | G19: Nychus | H19: FALSE | I19: FALSE | J19: Syndicate - Solaris United
B20: Cryotra | C20: TRUE | D20: FALSE | E20: Syndicate - Solaris United | G20: Oloro | H20: FALSE | I20: FALSE | J20: Syndicate - Solaris United
B21: Deconstructor | C21: TRUE | D21: TRUE | E21: Comes w/ Helios | G21: Para | H21: TRUE | I21: TRUE | J21: Syndicate - Solaris United
B22: Deth Machine Rifle | C22: TRUE | D22: TRUE | E22: Comes w/ Dethcube
B23: Helstrum | C23: TRUE | D23: FALSE | E23: Syndicate - Solaris United | G23: Predasites | H23: Acquired | I23: Mastered | J23: Method to Obtain
B24: Lacerten | C24: TRUE | D24: TRUE | E24: Comes w/ Bhaira Hound | G24: Medjay Predasite | H24: TRUE | I24: TRUE | J24: Syndicate - Entrati
B25: Laser Rifle | C25: TRUE | D25: TRUE | E25: Comes w/ Wyrm | G25: Pharaoh Predasite | H25: TRUE | I25: TRUE | J25: Syndicate - Entrati
B26: Multron | C26: TRUE | D26: FALSE | E26: Comes w/ Oxylus | G26: Vizier Predasite | H26: TRUE | I26: TRUE | J26: Syndicate - Entrati
B27: Prisma Burst Laser | C27: FALSE | D27: FALSE | E27: Comes w/ Prisma Shade
B28: Stinger | C28: TRUE | D28: TRUE | E28: Comes w/ Djinn | G28: Vulpaphyla | H28: Acquired | I28: Mastered | J28: Method to Obtain
B29: Sweeper | C29: TRUE | D29: TRUE | E29: Comes w/ Carrier | G29: Crescent Vulpaphyla | H29: TRUE | I29: TRUE | J29: Syndicate - Entrati
B30: Tazicor | C30: TRUE | D30: TRUE | E30: Syndicate - Solaris United | G30: Panzer Vulpaphyla | H30: TRUE | I30: TRUE | J30: Syndicate - Entrati
B31: Verglas | C31: FALSE | D31: FALSE | E31: Comes w/ Nautilus | G31: Sly Vulpaphyla | H31: TRUE | I31: TRUE | J31: Syndicate - Entrati
B32: Vulcax | C32: TRUE | D32: TRUE | E32: Syndicate - Solaris United
B33: Vulklok | C33: TRUE | D33: TRUE | E33: Comes w/ Diriga | G33: Hound | H33: Acquired | I33: Mastered | J33: Method to Obtain
G34: Bhaira | H34: TRUE | I34: TRUE | J34: Sisters of Parvos
B35: Prime Sentinels | C35: Acquired | D35: Mastered | E35: Method to Obtain | G35: Dorma | H35: FALSE | I35: FALSE | J35: Sisters of Parvos
B36: Carrier Prime | C36: FALSE | D36: FALSE | E36: Relics | G36: Hec | H36: FALSE | I36: FALSE | J36: Sisters of Parvos
B37: Dethcube Prime | C37: FALSE | D37: FALSE | E37: Relics
B38: Helios Prime | C38: FALSE | D38: FALSE | E38: Relics
B39: Nautilus Prime | C39: TRUE | D39: TRUE | E39: Relics
B40: Shade Prime | C40: FALSE | D40: FALSE | E40: Relics
...

Sheet Vehicle
B2: Archwings | C2: Acquired | D2: Mastered | E2: Method to Obtain | G2: Item | H2: Owned | I2: Completed
B3: Amesha | C3: TRUE | D3: TRUE | E3: Clan - Tenno Lab | G3: =B2 -> Archwings | H3: =COUNTIF(C3:C6, "TRUE") -> 4 | I3: =COUNTIF(D3:D6, "TRUE") -> 4
B4: Elytron | C4: TRUE | D4: TRUE | E4: Clan - Tenno Lab | G4: =B8 -> Prime | H4: =COUNTIF(C11, "TRUE") -> 0 | I4: =COUNTIF(D11, "TRUE") -> 0
B5: Itzal | C5: TRUE | D5: TRUE | E5: Clan - Tenno Lab | G5: Total | H5: =SUM(H3:H4) -> 4 | I5: =SUM(I3:I4) -> 4
B6: Odonata | C6: TRUE | D6: TRUE | E6: Quest - The Archwing | G6: Total Archwing | I6: =COUNTA(D3:D6,D11) -> 5
G7: =B13 -> Arch-Guns | H7: =COUNTIF(C14:C32, "TRUE") -> 8 | I7: =SUM(COUNTIF(D14:D30, "TRUE"),COUNTIF(D32, "TRUE")) -> 2
B8: Prime | C8: Acquired | D8: Mastered | E8: Method to Obtain | G8: Prime | H8: =COUNTIF(C9:C10, "TRUE") -> 0 | I8: =COUNTIF(D9:D10, "TRUE") -> 0
B9: Corvas Prime | C9: FALSE | D9: FALSE | E9: Relics | G9: Total | H9: =SUM(H7:H8) -> 8 | I9: =SUM(I7:I8) -> 2
B10: Larkspur Prime | C10: FALSE | D10: FALSE | E10: Relics | G10: Total Arch-Gun | I10: =COUNTA(,D14:D33, D9:D10) -2 -> 21
B11: Odonata Prime | C11: FALSE | D11: FALSE | E11: Relics (Baro Ki'Teer) | G11: Level 40 Archguns | I11: =SUM(COUNTIF(D31,TRUE),COUNTIF(D33,TRUE)) -> 0
G12: =B35 -> Arch-Melee | H12: =COUNTIF(C36:C43, "TRUE") -> 1 | I12: =COUNTIF(D36:D43, "TRUE") -> 1
B13: Arch-Guns | C13: Acquired | D13: Mastered | E13: Method to Obtain | G13: Total Arch-Melee | I13: =COUNTA(D36:D43) -> 8
B14: Arbucep | C14: TRUE | D14: FALSE | E14: Deepmines Bounties | G14: =B45 -> K-Drive | H14: =COUNTIF(C46:C50, "TRUE") -> 1 | I14: =COUNTIF(D46:D50, "TRUE") -> 0
B15: Cortege | C15: FALSE | D15: FALSE | E15: Syndicate - Necraloid | G15: Total K-Drive | I15: =COUNTA(D46:D50) -> 5
B16: Corvas | C16: TRUE | D16: FALSE | E16: Market | G16: Necramech | H16: =COUNTIF(C53:C55, "TRUE") -> 1 | I16: =(COUNTIF(D53, "TRUE")+COUNTIF(D55, "TRUE")) -> 1
B17: Cyngas | C17: FALSE | D17: FALSE | E17: Market | G17: Total Necramech | I17: =COUNTA(D53,D55) -> 2
B18: Dual Decurion | C18: TRUE | D18: FALSE | E18: Market | G18: Level 40 Necramechs | I18: =SUM(COUNTIF(D54,TRUE),COUNTIF(D56,TRUE)) -> 1
B19: Fluctus | C19: FALSE | D19: FALSE | E19: Clan - Tenno Lab | G19: Intrinsics | I19: =SUM(H25:H29) -> 41
B20: Grattler | C20: TRUE | D20: FALSE | E20: Clan - Chem Lab | G20: Total Intrinsics | I20: 50
B21: Imperator | C21: TRUE | D21: TRUE | E21: Comes w/ Odonata
B22: Imperator Vandal | C22: TRUE | D22: FALSE | E22: Mission - Balor Fomorian Invasion | G22: Plexus | H22: TRUE
B23: Larkspur | C23: FALSE | D23: FALSE | E23: Clan - Tenno Lab
B24: Mandonel | C24: TRUE | D24: FALSE | E24: Mission- Sanctum Anatomica | G24: Intrinsic | H24: Level
B25: Mausolon | C25: TRUE | D25: TRUE | E25: Comes w/ Necramech | G25: Tactical | H25: 8
B26: Morgha | C26: FALSE | D26: FALSE | E26: Syndicate - Necraloid | G26: Piloting | H26: 8
B27: Phaedra | C27: FALSE | D27: FALSE | E27: Market | G27: Gunnery | H27: 9
B28: Prisma Dual Decurion | C28: FALSE | D28: FALSE | E28: Baro Ki'teer | G28: Engineering | H28: 8
B29: Velocitus | C29: FALSE | D29: FALSE | E29: Clan - Tenno Lab | G29: Command | H29: 8
B30: Kuva Ayanga | C30: FALSE | D30: FALSE | E30: Kuva Lich
B31: - Ranks 30-40 | D31: FALSE
B32: Kuva Grattler | C32: FALSE | D32: FALSE | E32: Kuva Lich
B33: - Ranks 30 - 40 | D33: FALSE
B35: Arch-Melee | C35: Acquired | D35: Mastered | E35: Method to Obtain
B36: Agkuza | C36: FALSE | D36: FALSE | E36: Market
B37: Centaur | C37: FALSE | D37: FALSE | E37: Market
B38: Kaszas | C38: FALSE | D38: FALSE | E38: Market
B39: Knux | C39: FALSE | D39: FALSE | E39: Clan: Chem Lab - Uses Furax to craft
B40: Onorix | C40: FALSE | D40: FALSE | E40: Market
B41: Prisma Veritux | C41: FALSE | D41: FALSE | E41: Baro Ki'teer
B42: Rathbone | C42: FALSE | D42: FALSE | E42: Market
...

Sheet AmpDrifter
B2: Amp | C2: Acquired | D2: Mastered | E2: Method to Obtain | G2: Item | H2: Owned | I2: Completed
B3: Cantic Prism | C3: TRUE | D3: TRUE | E3: Syndicate - Vox Solaris | G3: =B2 -> Amp | H3: =COUNTIF(C3:C11, "TRUE") -> 5 | I3: =COUNTIF(D3:D11, "TRUE") -> 5
B4: Granmu Prism | C4: FALSE | D4: FALSE | E4: Syndicate - The Quills | G4: Total Amp | I4: =COUNTA(D2:D11) -> 10
B5: Klamora Prism | C5: TRUE | D5: TRUE | E5: Syndicate - Vox Solaris | G5: Intrinsics | I5: =SUM(I10:I13) -> 38
B6: Lega Prism | C6: FALSE | D6: FALSE | E6: Syndicate - Vox Solaris | G6: Total Intrinsics | I6: 40
B7: Mote Prism | C7: TRUE | D7: TRUE | E7: Quest - Saya's Vigil
B8: Rahn Prism | C8: FALSE | D8: FALSE | E8: Syndicate - The Quills
B9: Raplak Prism | C9: FALSE | D9: FALSE | E9: Syndicate - The Quills | H9: Drifter Intrinsic | I9: Level
B10: Shwaak Prism | C10: TRUE | D10: TRUE | E10: Syndicate - The Quills | H10: Combat | I10: 10
B11: Sirocco | C11: TRUE | D11: TRUE | E11: Quest - The New War | H11: Riding | I11: 10
H12: Opportunity | I12: 9
H13: Endurance | I13: 9
